Workbook
Name Spot: Pricer!$B$5
Name Strike: Pricer!$B$6
Name Maturity: Pricer!$B$7
Name Rate: Pricer!$B$8
Name Vol: Pricer!$B$9
Name DivYield: Pricer!$B$10
Name OptType: Pricer!$B$11

Sheet Pricer
A1: Black-Scholes option pricer
A2: Edit the yellow cells. Everything else is computed with Excel formulas.
A4: Inputs
A5: Spot (S) | B5: 100 | C5: Underlying price
A6: Strike (K) | B6: 100
A7: Maturity in years (T) | B7: 1 | C7: e.g. 0.5 = 6 months
A8: Risk-free rate (r) | B8: 0.05 | C8: Continuously compounded
A9: Volatility (sigma) | B9: 0.2 | C9: Annualised
A10: Dividend yield (q) | B10: 0 | C10: Continuous
A11: Type (Call / Put) | B11: Call | C11: Drop-down list
A13: Intermediate
A14: d1 | B14: =(LN(Spot/Strike)+(Rate-DivYield+Vol^2/2)*Maturity)/(Vol*SQRT(Maturity))
A15: d2 | B15: =B14-Vol*SQRT(Maturity)
A16: Sign (+1 call, -1 put) | B16: =IF(OptType="Call",1,-1)
A18: Results
A19: Price | B19: =B16*(Spot*EXP(-DivYield*Maturity)*NORMSDIST(B16*B14)-Strike*EXP(-Rate*Maturity)*NORMSDIST(B16*B15))
A20: Delta | B20: =B16*EXP(-DivYield*Maturity)*NORMSDIST(B16*B14) | C20: per 1 unit of spot
A21: Gamma | B21: =EXP(-DivYield*Maturity)*EXP(-B14^2/2)/SQRT(2*PI())/(Spot*Vol*SQRT(Maturity))
A22: Vega (per 1 vol point) | B22: =Spot*EXP(-DivYield*Maturity)*EXP(-B14^2/2)/SQRT(2*PI())*SQRT(Maturity)/100 | C22: change for +1% volatility
A23: Theta (per calendar day) | B23: =(-Spot*EXP(-DivYield*Maturity)*EXP(-B14^2/2)/SQRT(2*PI())*Vol/(2*SQRT(Maturity))-B16*Rate*Strike*EXP(-Rate*Maturity)*NORMSDIST(B16*B15)+B16*DivYield*Spot*EXP(-DivYield*Maturity)*NORMSDIST(B16*B14))/365 | C23: annual theta / 365
A24: Rho (per 1% rate) | B24: =B16*Strike*Maturity*EXP(-Rate*Maturity)*NORMSDIST(B16*B15)/100 | C24: change for +1% rate
A25: Forward value S.e^(-qT) - K.e^(-rT) | B25: =Spot*EXP(-DivYield*Maturity)-Strike*EXP(-Rate*Maturity) | C25: C - P should equal this

Sheet Chart data
A1: Spot | B1: Option price | C1: Payoff
A2: =Strike*(0.5+0/40) | B2: =Pricer!$B$16*(A2*EXP(-DivYield*Maturity)*NORMSDIST(Pricer!$B$16*((LN(A2/Strike)+(Rate-DivYield+Vol^2/2)*Maturity)/(Vol*SQRT(Maturity))))-Strike*EXP(-Rate*Maturity)*NORMSDIST(Pricer!$B$16*(((LN(A2/Strike)+(Rate-DivYield+Vol^2/2)*Maturity)/(Vol*SQRT(Maturity)))-Vol*SQRT(Maturity)))) | C2: =MAX(Pricer!$B$16*(A2-Strike),0)
A3: =Strike*(0.5+1/40) | B3: =Pricer!$B$16*(A3*EXP(-DivYield*Maturity)*NORMSDIST(Pricer!$B$16*((LN(A3/Strike)+(Rate-DivYield+Vol^2/2)*Maturity)/(Vol*SQRT(Maturity))))-Strike*EXP(-Rate*Maturity)*NORMSDIST(Pricer!$B$16*(((LN(A3/Strike)+(Rate-DivYield+Vol^2/2)*Maturity)/(Vol*SQRT(Maturity)))-Vol*SQRT(Maturity)))) | C3: =MAX(Pricer!$B$16*(A3-Strike),0)
A4: =Strike*(0.5+2/40) | B4: =Pricer!$B$16*(A4*EXP(-DivYield*Maturity)*NORMSDIST(Pricer!$B$16*((LN(A4/Strike)+(Rate-DivYield+Vol^2/2)*Maturity)/(Vol*SQRT(Maturity))))-Strike*EXP(-Rate*Maturity)*NORMSDIST(Pricer!$B$16*(((LN(A4/Strike)+(Rate-DivYield+Vol^2/2)*Maturity)/(Vol*SQRT(Maturity)))-Vol*SQRT(Maturity)))) | C4: =MAX(Pricer!$B$16*(A4-Strike),0)
A5: =Strike*(0.5+3/40) | B5: =Pricer!$B$16*(A5*EXP(-DivYield*Maturity)*NORMSDIST(Pricer!$B$16*((LN(A5/Strike)+(Rate-DivYield+Vol^2/2)*Maturity)/(Vol*SQRT(Maturity))))-Strike*EXP(-Rate*Maturity)*NORMSDIST(Pricer!$B$16*(((LN(A5/Strike)+(Rate-DivYield+Vol^2/2)*Maturity)/(Vol*SQRT(Maturity)))-Vol*SQRT(Maturity)))) | C5: =MAX(Pricer!$B$16*(A5-Strike),0)
A6: =Strike*(0.5+4/40) | B6: =Pricer!$B$16*(A6*EXP(-DivYield*Maturity)*NORMSDIST(Pricer!$B$16*((LN(A6/Strike)+(Rate-DivYield+Vol^2/2)*Maturity)/(Vol*SQRT(Maturity))))-Strike*EXP(-Rate*Maturity)*NORMSDIST(Pricer!$B$16*(((LN(A6/Strike)+(Rate-DivYield+Vol^2/2)*Maturity)/(Vol*SQRT(Maturity)))-Vol*SQRT(Maturity)))) | C6: =MAX(Pricer!$B$16*(A6-Strike),0)
A7: =Strike*(0.5+5/40) | B7: =Pricer!$B$16*(A7*EXP(-DivYield*Maturity)*NORMSDIST(Pricer!$B$16*((LN(A7/Strike)+(Rate-DivYield+Vol^2/2)*Maturity)/(Vol*SQRT(Maturity))))-Strike*EXP(-Rate*Maturity)*NORMSDIST(Pricer!$B$16*(((LN(A7/Strike)+(Rate-DivYield+Vol^2/2)*Maturity)/(Vol*SQRT(Maturity)))-Vol*SQRT(Maturity)))) | C7: =MAX(Pricer!$B$16*(A7-Strike),0)
A8: =Strike*(0.5+6/40) | B8: =Pricer!$B$16*(A8*EXP(-DivYield*Maturity)*NORMSDIST(Pricer!$B$16*((LN(A8/Strike)+(Rate-DivYield+Vol^2/2)*Maturity)/(Vol*SQRT(Maturity))))-Strike*EXP(-Rate*Maturity)*NORMSDIST(Pricer!$B$16*(((LN(A8/Strike)+(Rate-DivYield+Vol^2/2)*Maturity)/(Vol*SQRT(Maturity)))-Vol*SQRT(Maturity)))) | C8: =MAX(Pricer!$B$16*(A8-Strike),0)
A9: =Strike*(0.5+7/40) | B9: =Pricer!$B$16*(A9*EXP(-DivYield*Maturity)*NORMSDIST(Pricer!$B$16*((LN(A9/Strike)+(Rate-DivYield+Vol^2/2)*Maturity)/(Vol*SQRT(Maturity))))-Strike*EXP(-Rate*Maturity)*NORMSDIST(Pricer!$B$16*(((LN(A9/Strike)+(Rate-DivYield+Vol^2/2)*Maturity)/(Vol*SQRT(Maturity)))-Vol*SQRT(Maturity)))) | C9: =MAX(Pricer!$B$16*(A9-Strike),0)
A10: =Strike*(0.5+8/40) | B10: =Pricer!$B$16*(A10*EXP(-DivYield*Maturity)*NORMSDIST(Pricer!$B$16*((LN(A10/Strike)+(Rate-DivYield+Vol^2/2)*Maturity)/(Vol*SQRT(Maturity))))-Strike*EXP(-Rate*Maturity)*NORMSDIST(Pricer!$B$16*(((LN(A10/Strike)+(Rate-DivYield+Vol^2/2)*Maturity)/(Vol*SQRT(Maturity)))-Vol*SQRT(Maturity)))) | C10: =MAX(Pricer!$B$16*(A10-Strike),0)
A11: =Strike*(0.5+9/40) | B11: =Pricer!$B$16*(A11*EXP(-DivYield*Maturity)*NORMSDIST(Pricer!$B$16*((LN(A11/Strike)+(Rate-DivYield+Vol^2/2)*Maturity)/(Vol*SQRT(Maturity))))-Strike*EXP(-Rate*Maturity)*NORMSDIST(Pricer!$B$16*(((LN(A11/Strike)+(Rate-DivYield+Vol^2/2)*Maturity)/(Vol*SQRT(Maturity)))-Vol*SQRT(Maturity)))) | C11: =MAX(Pricer!$B$16*(A11-Strike),0)
A12: =Strike*(0.5+10/40) | B12: =Pricer!$B$16*(A12*EXP(-DivYield*Maturity)*NORMSDIST(Pricer!$B$16*((LN(A12/Strike)+(Rate-DivYield+Vol^2/2)*Maturity)/(Vol*SQRT(Maturity))))-Strike*EXP(-Rate*Maturity)*NORMSDIST(Pricer!$B$16*(((LN(A12/Strike)+(Rate-DivYield+Vol^2/2)*Maturity)/(Vol*SQRT(Maturity)))-Vol*SQRT(Maturity)))) | C12: =MAX(Pricer!$B$16*(A12-Strike),0)
A13: =Strike*(0.5+11/40) | B13: =Pricer!$B$16*(A13*EXP(-DivYield*Maturity)*NORMSDIST(Pricer!$B$16*((LN(A13/Strike)+(Rate-DivYield+Vol^2/2)*Maturity)/(Vol*SQRT(Maturity))))-Strike*EXP(-Rate*Maturity)*NORMSDIST(Pricer!$B$16*(((LN(A13/Strike)+(Rate-DivYield+Vol^2/2)*Maturity)/(Vol*SQRT(Maturity)))-Vol*SQRT(Maturity)))) | C13: =MAX(Pricer!$B$16*(A13-Strike),0)
A14: =Strike*(0.5+12/40) | B14: =Pricer!$B$16*(A14*EXP(-DivYield*Maturity)*NORMSDIST(Pricer!$B$16*((LN(A14/Strike)+(Rate-DivYield+Vol^2/2)*Maturity)/(Vol*SQRT(Maturity))))-Strike*EXP(-Rate*Maturity)*NORMSDIST(Pricer!$B$16*(((LN(A14/Strike)+(Rate-DivYield+Vol^2/2)*Maturity)/(Vol*SQRT(Maturity)))-Vol*SQRT(Maturity)))) | C14: =MAX(Pricer!$B$16*(A14-Strike),0)
A15: =Strike*(0.5+13/40) | B15: =Pricer!$B$16*(A15*EXP(-DivYield*Maturity)*NORMSDIST(Pricer!$B$16*((LN(A15/Strike)+(Rate-DivYield+Vol^2/2)*Maturity)/(Vol*SQRT(Maturity))))-Strike*EXP(-Rate*Maturity)*NORMSDIST(Pricer!$B$16*(((LN(A15/Strike)+(Rate-DivYield+Vol^2/2)*Maturity)/(Vol*SQRT(Maturity)))-Vol*SQRT(Maturity)))) | C15: =MAX(Pricer!$B$16*(A15-Strike),0)
A16: =Strike*(0.5+14/40) | B16: =Pricer!$B$16*(A16*EXP(-DivYield*Maturity)*NORMSDIST(Pricer!$B$16*((LN(A16/Strike)+(Rate-DivYield+Vol^2/2)*Maturity)/(Vol*SQRT(Maturity))))-Strike*EXP(-Rate*Maturity)*NORMSDIST(Pricer!$B$16*(((LN(A16/Strike)+(Rate-DivYield+Vol^2/2)*Maturity)/(Vol*SQRT(Maturity)))-Vol*SQRT(Maturity)))) | C16: =MAX(Pricer!$B$16*(A16-Strike),0)
A17: =Strike*(0.5+15/40) | B17: =Pricer!$B$16*(A17*EXP(-DivYield*Maturity)*NORMSDIST(Pricer!$B$16*((LN(A17/Strike)+(Rate-DivYield+Vol^2/2)*Maturity)/(Vol*SQRT(Maturity))))-Strike*EXP(-Rate*Maturity)*NORMSDIST(Pricer!$B$16*(((LN(A17/Strike)+(Rate-DivYield+Vol^2/2)*Maturity)/(Vol*SQRT(Maturity)))-Vol*SQRT(Maturity)))) | C17: =MAX(Pricer!$B$16*(A17-Strike),0)
A18: =Strike*(0.5+16/40) | B18: =Pricer!$B$16*(A18*EXP(-DivYield*Maturity)*NORMSDIST(Pricer!$B$16*((LN(A18/Strike)+(Rate-DivYield+Vol^2/2)*Maturity)/(Vol*SQRT(Maturity))))-Strike*EXP(-Rate*Maturity)*NORMSDIST(Pricer!$B$16*(((LN(A18/Strike)+(Rate-DivYield+Vol^2/2)*Maturity)/(Vol*SQRT(Maturity)))-Vol*SQRT(Maturity)))) | C18: =MAX(Pricer!$B$16*(A18-Strike),0)
A19: =Strike*(0.5+17/40) | B19: =Pricer!$B$16*(A19*EXP(-DivYield*Maturity)*NORMSDIST(Pricer!$B$16*((LN(A19/Strike)+(Rate-DivYield+Vol^2/2)*Maturity)/(Vol*SQRT(Maturity))))-Strike*EXP(-Rate*Maturity)*NORMSDIST(Pricer!$B$16*(((LN(A19/Strike)+(Rate-DivYield+Vol^2/2)*Maturity)/(Vol*SQRT(Maturity)))-Vol*SQRT(Maturity)))) | C19: =MAX(Pricer!$B$16*(A19-Strike),0)
A20: =Strike*(0.5+18/40) | B20: =Pricer!$B$16*(A20*EXP(-DivYield*Maturity)*NORMSDIST(Pricer!$B$16*((LN(A20/Strike)+(Rate-DivYield+Vol^2/2)*Maturity)/(Vol*SQRT(Maturity))))-Strike*EXP(-Rate*Maturity)*NORMSDIST(Pricer!$B$16*(((LN(A20/Strike)+(Rate-DivYield+Vol^2/2)*Maturity)/(Vol*SQRT(Maturity)))-Vol*SQRT(Maturity)))) | C20: =MAX(Pricer!$B$16*(A20-Strike),0)
A21: =Strike*(0.5+19/40) | B21: =Pricer!$B$16*(A21*EXP(-DivYield*Maturity)*NORMSDIST(Pricer!$B$16*((LN(A21/Strike)+(Rate-DivYield+Vol^2/2)*Maturity)/(Vol*SQRT(Maturity))))-Strike*EXP(-Rate*Maturity)*NORMSDIST(Pricer!$B$16*(((LN(A21/Strike)+(Rate-DivYield+Vol^2/2)*Maturity)/(Vol*SQRT(Maturity)))-Vol*SQRT(Maturity)))) | C21: =MAX(Pricer!$B$16*(A21-Strike),0)
A22: =Strike*(0.5+20/40) | B22: =Pricer!$B$16*(A22*EXP(-DivYield*Maturity)*NORMSDIST(Pricer!$B$16*((LN(A22/Strike)+(Rate-DivYield+Vol^2/2)*Maturity)/(Vol*SQRT(Maturity))))-Strike*EXP(-Rate*Maturity)*NORMSDIST(Pricer!$B$16*(((LN(A22/Strike)+(Rate-DivYield+Vol^2/2)*Maturity)/(Vol*SQRT(Maturity)))-Vol*SQRT(Maturity)))) | C22: =MAX(Pricer!$B$16*(A22-Strike),0)
A23: =Strike*(0.5+21/40) | B23: =Pricer!$B$16*(A23*EXP(-DivYield*Maturity)*NORMSDIST(Pricer!$B$16*((LN(A23/Strike)+(Rate-DivYield+Vol^2/2)*Maturity)/(Vol*SQRT(Maturity))))-Strike*EXP(-Rate*Maturity)*NORMSDIST(Pricer!$B$16*(((LN(A23/Strike)+(Rate-DivYield+Vol^2/2)*Maturity)/(Vol*SQRT(Maturity)))-Vol*SQRT(Maturity)))) | C23: =MAX(Pricer!$B$16*(A23-Strike),0)
A24: =Strike*(0.5+22/40) | B24: =Pricer!$B$16*(A24*EXP(-DivYield*Maturity)*NORMSDIST(Pricer!$B$16*((LN(A24/Strike)+(Rate-DivYield+Vol^2/2)*Maturity)/(Vol*SQRT(Maturity))))-Strike*EXP(-Rate*Maturity)*NORMSDIST(Pricer!$B$16*(((LN(A24/Strike)+(Rate-DivYield+Vol^2/2)*Maturity)/(Vol*SQRT(Maturity)))-Vol*SQRT(Maturity)))) | C24: =MAX(Pricer!$B$16*(A24-Strike),0)
A25: =Strike*(0.5+23/40) | B25: =Pricer!$B$16*(A25*EXP(-DivYield*Maturity)*NORMSDIST(Pricer!$B$16*((LN(A25/Strike)+(Rate-DivYield+Vol^2/2)*Maturity)/(Vol*SQRT(Maturity))))-Strike*EXP(-Rate*Maturity)*NORMSDIST(Pricer!$B$16*(((LN(A25/Strike)+(Rate-DivYield+Vol^2/2)*Maturity)/(Vol*SQRT(Maturity)))-Vol*SQRT(Maturity)))) | C25: =MAX(Pricer!$B$16*(A25-Strike),0)
A26: =Strike*(0.5+24/40) | B26: =Pricer!$B$16*(A26*EXP(-DivYield*Maturity)*NORMSDIST(Pricer!$B$16*((LN(A26/Strike)+(Rate-DivYield+Vol^2/2)*Maturity)/(Vol*SQRT(Maturity))))-Strike*EXP(-Rate*Maturity)*NORMSDIST(Pricer!$B$16*(((LN(A26/Strike)+(Rate-DivYield+Vol^2/2)*Maturity)/(Vol*SQRT(Maturity)))-Vol*SQRT(Maturity)))) | C26: =MAX(Pricer!$B$16*(A26-Strike),0)
A27: =Strike*(0.5+25/40) | B27: =Pricer!$B$16*(A27*EXP(-DivYield*Maturity)*NORMSDIST(Pricer!$B$16*((LN(A27/Strike)+(Rate-DivYield+Vol^2/2)*Maturity)/(Vol*SQRT(Maturity))))-Strike*EXP(-Rate*Maturity)*NORMSDIST(Pricer!$B$16*(((LN(A27/Strike)+(Rate-DivYield+Vol^2/2)*Maturity)/(Vol*SQRT(Maturity)))-Vol*SQRT(Maturity)))) | C27: =MAX(Pricer!$B$16*(A27-Strike),0)
A28: =Strike*(0.5+26/40) | B28: =Pricer!$B$16*(A28*EXP(-DivYield*Maturity)*NORMSDIST(Pricer!$B$16*((LN(A28/Strike)+(Rate-DivYield+Vol^2/2)*Maturity)/(Vol*SQRT(Maturity))))-Strike*EXP(-Rate*Maturity)*NORMSDIST(Pricer!$B$16*(((LN(A28/Strike)+(Rate-DivYield+Vol^2/2)*Maturity)/(Vol*SQRT(Maturity)))-Vol*SQRT(Maturity)))) | C28: =MAX(Pricer!$B$16*(A28-Strike),0)
A29: =Strike*(0.5+27/40) | B29: =Pricer!$B$16*(A29*EXP(-DivYield*Maturity)*NORMSDIST(Pricer!$B$16*((LN(A29/Strike)+(Rate-DivYield+Vol^2/2)*Maturity)/(Vol*SQRT(Maturity))))-Strike*EXP(-Rate*Maturity)*NORMSDIST(Pricer!$B$16*(((LN(A29/Strike)+(Rate-DivYield+Vol^2/2)*Maturity)/(Vol*SQRT(Maturity)))-Vol*SQRT(Maturity)))) | C29: =MAX(Pricer!$B$16*(A29-Strike),0)
A30: =Strike*(0.5+28/40) | B30: =Pricer!$B$16*(A30*EXP(-DivYield*Maturity)*NORMSDIST(Pricer!$B$16*((LN(A30/Strike)+(Rate-DivYield+Vol^2/2)*Maturity)/(Vol*SQRT(Maturity))))-Strike*EXP(-Rate*Maturity)*NORMSDIST(Pricer!$B$16*(((LN(A30/Strike)+(Rate-DivYield+Vol^2/2)*Maturity)/(Vol*SQRT(Maturity)))-Vol*SQRT(Maturity)))) | C30: =MAX(Pricer!$B$16*(A30-Strike),0)
A31: =Strike*(0.5+29/40) | B31: =Pricer!$B$16*(A31*EXP(-DivYield*Maturity)*NORMSDIST(Pricer!$B$16*((LN(A31/Strike)+(Rate-DivYield+Vol^2/2)*Maturity)/(Vol*SQRT(Maturity))))-Strike*EXP(-Rate*Maturity)*NORMSDIST(Pricer!$B$16*(((LN(A31/Strike)+(Rate-DivYield+Vol^2/2)*Maturity)/(Vol*SQRT(Maturity)))-Vol*SQRT(Maturity)))) | C31: =MAX(Pricer!$B$16*(A31-Strike),0)
A32: =Strike*(0.5+30/40) | B32: =Pricer!$B$16*(A32*EXP(-DivYield*Maturity)*NORMSDIST(Pricer!$B$16*((LN(A32/Strike)+(Rate-DivYield+Vol^2/2)*Maturity)/(Vol*SQRT(Maturity))))-Strike*EXP(-Rate*Maturity)*NORMSDIST(Pricer!$B$16*(((LN(A32/Strike)+(Rate-DivYield+Vol^2/2)*Maturity)/(Vol*SQRT(Maturity)))-Vol*SQRT(Maturity)))) | C32: =MAX(Pricer!$B$16*(A32-Strike),0)
A33: =Strike*(0.5+31/40) | B33: =Pricer!$B$16*(A33*EXP(-DivYield*Maturity)*NORMSDIST(Pricer!$B$16*((LN(A33/Strike)+(Rate-DivYield+Vol^2/2)*Maturity)/(Vol*SQRT(Maturity))))-Strike*EXP(-Rate*Maturity)*NORMSDIST(Pricer!$B$16*(((LN(A33/Strike)+(Rate-DivYield+Vol^2/2)*Maturity)/(Vol*SQRT(Maturity)))-Vol*SQRT(Maturity)))) | C33: =MAX(Pricer!$B$16*(A33-Strike),0)
A34: =Strike*(0.5+32/40) | B34: =Pricer!$B$16*(A34*EXP(-DivYield*Maturity)*NORMSDIST(Pricer!$B$16*((LN(A34/Strike)+(Rate-DivYield+Vol^2/2)*Maturity)/(Vol*SQRT(Maturity))))-Strike*EXP(-Rate*Maturity)*NORMSDIST(Pricer!$B$16*(((LN(A34/Strike)+(Rate-DivYield+Vol^2/2)*Maturity)/(Vol*SQRT(Maturity)))-Vol*SQRT(Maturity)))) | C34: =MAX(Pricer!$B$16*(A34-Strike),0)
A35: =Strike*(0.5+33/40) | B35: =Pricer!$B$16*(A35*EXP(-DivYield*Maturity)*NORMSDIST(Pricer!$B$16*((LN(A35/Strike)+(Rate-DivYield+Vol^2/2)*Maturity)/(Vol*SQRT(Maturity))))-Strike*EXP(-Rate*Maturity)*NORMSDIST(Pricer!$B$16*(((LN(A35/Strike)+(Rate-DivYield+Vol^2/2)*Maturity)/(Vol*SQRT(Maturity)))-Vol*SQRT(Maturity)))) | C35: =MAX(Pricer!$B$16*(A35-Strike),0)
A36: =Strike*(0.5+34/40) | B36: =Pricer!$B$16*(A36*EXP(-DivYield*Maturity)*NORMSDIST(Pricer!$B$16*((LN(A36/Strike)+(Rate-DivYield+Vol^2/2)*Maturity)/(Vol*SQRT(Maturity))))-Strike*EXP(-Rate*Maturity)*NORMSDIST(Pricer!$B$16*(((LN(A36/Strike)+(Rate-DivYield+Vol^2/2)*Maturity)/(Vol*SQRT(Maturity)))-Vol*SQRT(Maturity)))) | C36: =MAX(Pricer!$B$16*(A36-Strike),0)
A37: =Strike*(0.5+35/40) | B37: =Pricer!$B$16*(A37*EXP(-DivYield*Maturity)*NORMSDIST(Pricer!$B$16*((LN(A37/Strike)+(Rate-DivYield+Vol^2/2)*Maturity)/(Vol*SQRT(Maturity))))-Strike*EXP(-Rate*Maturity)*NORMSDIST(Pricer!$B$16*(((LN(A37/Strike)+(Rate-DivYield+Vol^2/2)*Maturity)/(Vol*SQRT(Maturity)))-Vol*SQRT(Maturity)))) | C37: =MAX(Pricer!$B$16*(A37-Strike),0)
A38: =Strike*(0.5+36/40) | B38: =Pricer!$B$16*(A38*EXP(-DivYield*Maturity)*NORMSDIST(Pricer!$B$16*((LN(A38/Strike)+(Rate-DivYield+Vol^2/2)*Maturity)/(Vol*SQRT(Maturity))))-Strike*EXP(-Rate*Maturity)*NORMSDIST(Pricer!$B$16*(((LN(A38/Strike)+(Rate-DivYield+Vol^2/2)*Maturity)/(Vol*SQRT(Maturity)))-Vol*SQRT(Maturity)))) | C38: =MAX(Pricer!$B$16*(A38-Strike),0)
A39: =Strike*(0.5+37/40) | B39: =Pricer!$B$16*(A39*EXP(-DivYield*Maturity)*NORMSDIST(Pricer!$B$16*((LN(A39/Strike)+(Rate-DivYield+Vol^2/2)*Maturity)/(Vol*SQRT(Maturity))))-Strike*EXP(-Rate*Maturity)*NORMSDIST(Pricer!$B$16*(((LN(A39/Strike)+(Rate-DivYield+Vol^2/2)*Maturity)/(Vol*SQRT(Maturity)))-Vol*SQRT(Maturity)))) | C39: =MAX(Pricer!$B$16*(A39-Strike),0)
A40: =Strike*(0.5+38/40) | B40: =Pricer!$B$16*(A40*EXP(-DivYield*Maturity)*NORMSDIST(Pricer!$B$16*((LN(A40/Strike)+(Rate-DivYield+Vol^2/2)*Maturity)/(Vol*SQRT(Maturity))))-Strike*EXP(-Rate*Maturity)*NORMSDIST(Pricer!$B$16*(((LN(A40/Strike)+(Rate-DivYield+Vol^2/2)*Maturity)/(Vol*SQRT(Maturity)))-Vol*SQRT(Maturity)))) | C40: =MAX(Pricer!$B$16*(A40-Strike),0)
...

Sheet Notes
A1: Model: Black-Scholes-Merton for European options, continuous dividend yield.
A2: Uses only long-standing functions (NORMSDIST, LN, EXP), so it works in any Excel version and LibreOffice.
A3: Greeks: vega and rho per 1 percentage point, theta per calendar day (annual / 365).
A4: American options and Monte Carlo are only in the Python package (option_pricer).
A5: Optional: vba/BlackScholes.bas adds a =BS_PRICE(...) user function (see README).
